Workbook

Sheet Roster
A1: Men's League Basketball Stat Tracker | B1: Men's League Basketball Stat Tracker | C1: Men's League Basketball Stat Tracker | D1: Men's League Basketball Stat Tracker | E1: Men's League Basketball Stat Tracker
A3: Roster | B3: Roster | C3: Roster | D3: Roster | E3: Roster | G3: How to use
A4: Slot | B4: Jersey # | C4: Player Name | D4: Primary Position | E4: Active? | G4: 1. Fill roster names once.
A5: 1 | C5: Brendan Wong | D5: Guard | E5: Yes | G5: 2. Track the current game on Live Game Sheet.
A6: 2 | C6: Kevin Chen | D6: Guard | E6: Yes | G6: 3. After the game, paste player rows into Player Game Log with a Game ID.
A7: 3 | C7: Siddarth D | D7: Center | E7: Yes | G7: 4. Paste end-of-quarter total scores in Team Game Log.
A8: 4 | C8: Ethan Hu | D8: Forward | E8: Yes | G8: 5. Team DREB, OREB, TO, AST, FGA, and FTA summarize from player rows.
A9: 5 | C9: Kenny Liou | D9: Forward/Center | E9: Yes
A10: 6 | C10: Max Lee | D10: Forward | E10: Yes
A11: 7 | C11: Xuanyi W | D11: Guard | E11: Yes
A12: 8 | C12: Markus Wong | D12: Guard | E12: Yes
A13: 9 | C13: Thomas N | D13: Guard | E13: Yes
A14: 10 | C14: Arjun V | D14: Guard | E14: Yes
A15: 11 | C15: Yash S | D15: Forward | E15: Yes
A16: 12 | C16: Will | D16: Guard | E16: Yes
A17: 13 | C17: Steven | D17: Guard | E17: Yes
A18: 14 | C18: Vee | D18: Center | E18: Yes
A19: 15 | C19: Michael | D19: Forward/Guard | E19: No
A20: 16 | C20: Eddie | D20: Guard | E20: No
A21: 17 | C21: Stephen Zhong | D21: Forward | E21: No
A22: 18 | E22: No
A23: 19 | E23: No
A24: 20 | E24: No

Sheet Game 1 Stats Sheet
A1: Live Game Sheet | B1: Live Game Sheet | C1: Live Game Sheet | D1: Live Game Sheet | E1: Live Game Sheet | F1: Live Game Sheet | G1: Live Game Sheet | H1: Live Game Sheet | I1: Live Game Sheet | J1: Live Game Sheet | K1: Live Game Sheet | L1: Live Game Sheet | M1: Live Game Sheet | O1: Live Game Sheet | P1: Live Game Sheet | Q1: Live Game Sheet | R1: Live Game Sheet | S1: Live Game Sheet | T1: Live Game Sheet
A2: Game Date | B2: 7/270/2026 | D2: Opponent | E2: White | G2: Location | H2: Telegraph Hill Community Center
A4: Score: Enter Total Score At End Of Quarter | B4: Score: Enter Total Score At End Of Quarter | C4: Score: Enter Total Score At End Of Quarter | D4: Score: Enter Total Score At End Of Quarter | E4: Score: Enter Total Score At End Of Quarter | F4: Score: Enter Total Score At End Of Quarter | H4: Team Totals From Player Stats | I4: Team Totals From Player Stats | J4: Team Totals From Player Stats | K4: Team Totals From Player Stats | L4: Team Totals From Player Stats | M4: Team Totals From Player Stats | O4: Team Totals From Player Stats | P4: Team Totals From Player Stats | Q4: Team Totals From Player Stats | R4: Team Totals From Player Stats | S4: Team Totals From Player Stats | T4: Team Totals From Player Stats
A5: Team | B5: Q1 End Total | C5: Final Total | D5: Q1 Points | E5: Q2 Points | F5: Game Total | H5: 2PM | I5: 2PA | J5: 3PM | K5: 3PA | L5: FGM | M5: FGA | N5: FTM | O5: FTA | P5: DREB | Q5: OREB | R5: AST | S5: TO | T5: STL
A6: Our Team | B6: 17 | C6: 31 | D6: =IF(B6="","",B6) -> 17 | E6: =IF(OR(B6="",C6=""),"",C6-B6) -> 14 | F6: =IF(C6="","",C6) -> 31 | H6: =SUM(D10:D30) -> 10 | I6: =SUM(E10:E30) -> 30 | J6: =SUM(F10:F30) -> 2 | K6: =SUM(G10:G30) -> 30 | L6: =SUM(D10:D30)+SUM(F10:F30) -> 12 | M6: =SUM(E10:E30)+SUM(G10:G30) -> 60 | N6: =SUM(H10:H30) -> 5 | O6: =SUM(I10:I30) -> 11 | P6: =SUM(J10:J30) -> 24 | Q6: =SUM(K10:K30) -> 3 | R6: =SUM(L10:L30) -> 2 | S6: =SUM(M10:M30) -> 4 | T6: =SUM(N10:N30) -> 4
A7: Opponent | B7: 31 | C7: 67 | D7: =IF(B7="","",B7) -> 31 | E7: =IF(OR(B7="",C7=""),"",C7-B7) -> 36 | F7: =IF(C7="","",C7) -> 67 | H7: 2P% | I7: =H6/I6 -> 0.33333333 | J7: 3P% | K7: =J6/K6 -> 0.066666667 | L7: FG% | M7: =L6/M6 -> 0.2 | N7: FT% | O7: =N6/O6 -> 0.45454545
A9: Player Stat Entry | B9: Player Stat Entry | C9: Player Stat Entry | D9: Player Stat Entry | E9: Player Stat Entry | F9: Player Stat Entry | G9: Player Stat Entry | H9: Player Stat Entry | I9: Player Stat Entry | J9: Player Stat Entry | K9: Player Stat Entry | L9: Player Stat Entry | M9: Player Stat Entry | O9: Player Stat Entry | P9: Player Stat Entry | Q9: Player Stat Entry | R9: Player Stat Entry | S9: Player Stat Entry | T9: Player Stat Entry
A10: Slot | B10: Jersey # | C10: Player | D10: 2PM | E10: 2PA | F10: 3PM | G10: 3PA | H10: FTM | I10: FTA | J10: DREB | K10: OREB | L10: AST | M10: TrnOv | N10: STL | O10: FGM | P10: FGA | Q10: PTS | R10: FG% | S10: FT%
A11: 1 | B11: =IF(Roster!B5="","",Roster!B5) | C11: =IF(Roster!C5="","",Roster!C5) -> Brendan Wong | O11: =IF(SUM(D11,F11)=0,"",D11+F11) | P11: =IF(SUM(E11,G11)=0,"",E11+G11) | Q11: =IF(SUM(D11,F11,H11)=0,"",D11*2+F11*3+H11) | R11: =IF(P11="","",IF(O11="",0,O11/P11)) | S11: =IF(I11=0,"",H11/I11)
A12: 2 | B12: =IF(Roster!B6="","",Roster!B6) | C12: =IF(Roster!C6="","",Roster!C6) -> Kevin Chen | D12: 5 | E12: 14 | F12: 1 | G12: 2 | H12: 2 | I12: 8 | J12: 6 | K12: 0 | L12: 1 | M12: 2 | N12: 1 | O12: =IF(SUM(D12,F12)=0,"",D12+F12) -> 6 | P12: =IF(SUM(E12,G12)=0,"",E12+G12) -> 16 | Q12: =IF(SUM(D12,F12,H12)=0,"",D12*2+F12*3+H12) -> 15 | R12: =IF(P12="","",IF(O12="",0,O12/P12)) -> 0.375 | S12: =IF(I12=0,"",H12/I12) -> 0.25
A13: 3 | B13: =IF(Roster!B7="","",Roster!B7) | C13: =IF(Roster!C7="","",Roster!C7) -> Siddarth D | O13: =IF(SUM(D13,F13)=0,"",D13+F13) | P13: =IF(SUM(E13,G13)=0,"",E13+G13) | Q13: =IF(SUM(D13,F13,H13)=0,"",D13*2+F13*3+H13) | R13: =IF(P13="","",IF(O13="",0,O13/P13)) | S13: =IF(I13=0,"",H13/I13)
A14: 4 | B14: =IF(Roster!B8="","",Roster!B8) | C14: =IF(Roster!C8="","",Roster!C8) -> Ethan Hu | D14: 0 | E14: 1 | F14: 0 | G14: 4 | H14: 0 | I14: 0 | J14: 2 | K14: 0 | L14: 0 | M14: 1 | N14: 0 | O14: =IF(SUM(D14,F14)=0,"",D14+F14) | P14: =IF(SUM(E14,G14)=0,"",E14+G14) -> 5 | Q14: =IF(SUM(D14,F14,H14)=0,"",D14*2+F14*3+H14) | R14: =IF(P14="","",IF(O14="",0,O14/P14)) -> 0 | S14: =IF(I14=0,"",H14/I14)
A15: 5 | B15: =IF(Roster!B9="","",Roster!B9) | C15: =IF(Roster!C9="","",Roster!C9) -> Kenny Liou | D15: 0 | E15: 3 | F15: 0 | G15: 1 | H15: 0 | I15: 0 | J15: 5 | K15: 1 | L15: 0 | M15: 0 | N15: 1 | O15: =IF(SUM(D15,F15)=0,"",D15+F15) | P15: =IF(SUM(E15,G15)=0,"",E15+G15) -> 4 | Q15: =IF(SUM(D15,F15,H15)=0,"",D15*2+F15*3+H15) | R15: =IF(P15="","",IF(O15="",0,O15/P15)) -> 0 | S15: =IF(I15=0,"",H15/I15)
A16: 6 | B16: =IF(Roster!B10="","",Roster!B10) | C16: =IF(Roster!C10="","",Roster!C10) -> Max Lee | D16: 0 | E16: 0 | F16: 0 | G16: 7 | H16: 0 | I16: 0 | J16: 2 | K16: 1 | L16: 0 | M16: 0 | N16: 0 | O16: =IF(SUM(D16,F16)=0,"",D16+F16) | P16: =IF(SUM(E16,G16)=0,"",E16+G16) -> 7 | Q16: =IF(SUM(D16,F16,H16)=0,"",D16*2+F16*3+H16) | R16: =IF(P16="","",IF(O16="",0,O16/P16)) -> 0 | S16: =IF(I16=0,"",H16/I16)
A17: 7 | B17: =IF(Roster!B11="","",Roster!B11) | C17: =IF(Roster!C11="","",Roster!C11) -> Xuanyi W | D17: 1 | E17: 1 | F17: 1 | G17: 3 | H17: 0 | I17: 0 | J17: 4 | K17: 1 | L17: 0 | M17: 0 | N17: 1 | O17: =IF(SUM(D17,F17)=0,"",D17+F17) -> 2 | P17: =IF(SUM(E17,G17)=0,"",E17+G17) -> 4 | Q17: =IF(SUM(D17,F17,H17)=0,"",D17*2+F17*3+H17) -> 5 | R17: =IF(P17="","",IF(O17="",0,O17/P17)) -> 0.5 | S17: =IF(I17=0,"",H17/I17)
A18: 8 | B18: =IF(Roster!B12="","",Roster!B12) | C18: =IF(Roster!C12="","",Roster!C12) -> Markus Wong | D18: 0 | E18: 2 | F18: 0 | G18: 0 | H18: 0 | I18: 0 | J18: 0 | K18: 0 | L18: 0 | M18: 0 | N18: 0 | O18: =IF(SUM(D18,F18)=0,"",D18+F18) | P18: =IF(SUM(E18,G18)=0,"",E18+G18) -> 2 | Q18: =IF(SUM(D18,F18,H18)=0,"",D18*2+F18*3+H18) | R18: =IF(P18="","",IF(O18="",0,O18/P18)) -> 0 | S18: =IF(I18=0,"",H18/I18)
A19: 9 | B19: =IF(Roster!B13="","",Roster!B13) | C19: =IF(Roster!C13="","",Roster!C13) -> Thomas N | D19: 0 | E19: 0 | F19: 0 | G19: 3 | H19: 0 | I19: 0 | J19: 1 | K19: 0 | L19: 0 | M19: 0 | N19: 0 | O19: =IF(SUM(D19,F19)=0,"",D19+F19) | P19: =IF(SUM(E19,G19)=0,"",E19+G19) -> 3 | Q19: =IF(SUM(D19,F19,H19)=0,"",D19*2+F19*3+H19) | R19: =IF(P19="","",IF(O19="",0,O19/P19)) -> 0 | S19: =IF(I19=0,"",H19/I19)
A20: 10 | B20: =IF(Roster!B14="","",Roster!B14) | C20: =IF(Roster!C14="","",Roster!C14) -> Arjun V | D20: 4 | E20: 9 | F20: 0 | G20: 10 | H20: 3 | I20: 3 | J20: 4 | K20: 0 | L20: 1 | M20: 1 | N20: 1 | O20: =IF(SUM(D20,F20)=0,"",D20+F20) -> 4 | P20: =IF(SUM(E20,G20)=0,"",E20+G20) -> 19 | Q20: =IF(SUM(D20,F20,H20)=0,"",D20*2+F20*3+H20) -> 11 | R20: =IF(P20="","",IF(O20="",0,O20/P20)) -> 0.21052632 | S20: =IF(I20=0,"",H20/I20) -> 1
A21: 11 | B21: =IF(Roster!B15="","",Roster!B15) | C21: =IF(Roster!C15="","",Roster!C15) -> Yash S | O21: =IF(SUM(D21,F21)=0,"",D21+F21) | P21: =IF(SUM(E21,G21)=0,"",E21+G21) | Q21: =IF(SUM(D21,F21,H21)=0,"",D21*2+F21*3+H21) | R21: =IF(P21="","",IF(O21="",0,O21/P21)) | S21: =IF(I21=0,"",H21/I21)
A22: 12 | B22: =IF(Roster!B16="","",Roster!B16) | C22: =IF(Roster!C16="","",Roster!C16) -> Will | O22: =IF(SUM(D22,F22)=0,"",D22+F22) | P22: =IF(SUM(E22,G22)=0,"",E22+G22) | Q22: =IF(SUM(D22,F22,H22)=0,"",D22*2+F22*3+H22) | R22: =IF(P22="","",IF(O22="",0,O22/P22)) | S22: =IF(I22=0,"",H22/I22)
A23: 13 | B23: =IF(Roster!B17="","",Roster!B17) | C23: =IF(Roster!C17="","",Roster!C17) -> Steven | O23: =IF(SUM(D23,F23)=0,"",D23+F23) | P23: =IF(SUM(E23,G23)=0,"",E23+G23) | Q23: =IF(SUM(D23,F23,H23)=0,"",D23*2+F23*3+H23) | R23: =IF(P23="","",IF(O23="",0,O23/P23)) | S23: =IF(I23=0,"",H23/I23)
A24: 14 | B24: =IF(Roster!B18="","",Roster!B18) | C24: =IF(Roster!C18="","",Roster!C18) -> Vee | O24: =IF(SUM(D24,F24)=0,"",D24+F24) | P24: =IF(SUM(E24,G24)=0,"",E24+G24) | Q24: =IF(SUM(D24,F24,H24)=0,"",D24*2+F24*3+H24) | R24: =IF(P24="","",IF(O24="",0,O24/P24)) | S24: =IF(I24=0,"",H24/I24)
A25: 15 | B25: =IF(Roster!B19="","",Roster!B19) | C25: =IF(Roster!C19="","",Roster!C19) -> Michael | O25: =IF(SUM(D25,F25)=0,"",D25+F25) | P25: =IF(SUM(E25,G25)=0,"",E25+G25) | Q25: =IF(SUM(D25,F25,H25)=0,"",D25*2+F25*3+H25) | R25: =IF(P25="","",IF(O25="",0,O25/P25)) | S25: =IF(I25=0,"",H25/I25)
A26: 16 | B26: =IF(Roster!B20="","",Roster!B20) | C26: =IF(Roster!C20="","",Roster!C20) -> Eddie | O26: =IF(SUM(D26,F26)=0,"",D26+F26) | P26: =IF(SUM(E26,G26)=0,"",E26+G26) | Q26: =IF(SUM(D26,F26,H26)=0,"",D26*2+F26*3+H26) | R26: =IF(P26="","",IF(O26="",0,O26/P26)) | S26: =IF(I26=0,"",H26/I26)
A27: 17 | B27: =IF(Roster!B21="","",Roster!B21) | C27: =IF(Roster!C21="","",Roster!C21) -> Stephen Zhong | O27: =IF(SUM(D27,F27)=0,"",D27+F27) | P27: =IF(SUM(E27,G27)=0,"",E27+G27) | Q27: =IF(SUM(D27,F27,H27)=0,"",D27*2+F27*3+H27) | R27: =IF(P27="","",IF(O27="",0,O27/P27)) | S27: =IF(I27=0,"",H27/I27)
A28: 18 | B28: =IF(Roster!B22="","",Roster!B22) | C28: =IF(Roster!C22="","",Roster!C22) | O28: =IF(SUM(D28,F28)=0,"",D28+F28) | P28: =IF(SUM(E28,G28)=0,"",E28+G28) | Q28: =IF(SUM(D28,F28,H28)=0,"",D28*2+F28*3+H28) | R28: =IF(P28="","",IF(O28="",0,O28/P28)) | S28: =IF(I28=0,"",H28/I28)
A29: 19 | B29: =IF(Roster!B23="","",Roster!B23) | C29: =IF(Roster!C23="","",Roster!C23) | O29: =IF(SUM(D29,F29)=0,"",D29+F29) | P29: =IF(SUM(E29,G29)=0,"",E29+G29) | Q29: =IF(SUM(D29,F29,H29)=0,"",D29*2+F29*3+H29) | R29: =IF(P29="","",IF(O29="",0,O29/P29)) | S29: =IF(I29=0,"",H29/I29)
A30: 20 | B30: =IF(Roster!B24="","",Roster!B24) | C30: =IF(Roster!C24="","",Roster!C24) | O30: =IF(SUM(D30,F30)=0,"",D30+F30) | P30: =IF(SUM(E30,G30)=0,"",E30+G30) | Q30: =IF(SUM(D30,F30,H30)=0,"",D30*2+F30*3+H30) | R30: =IF(P30="","",IF(O30="",0,O30/P30)) | S30: =IF(I30=0,"",H30/I30)

Sheet Game 2 Stats Sheet
A1: Live Game Sheet
A2: Game Date | B2: 46230 | D2: Opponent | E2: Green | G2: Location | H2: Telegraph Hill Community Center
A4: Score: Enter Total Score At End Of Quarter | B4: Score: Enter Total Score At End Of Quarter | C4: Score: Enter Total Score At End Of Quarter | D4: Score: Enter Total Score At End Of Quarter | E4: Score: Enter Total Score At End Of Quarter | F4: Score: Enter Total Score At End Of Quarter | H4: Team Totals From Player Stats
A5: Team | B5: Q1 End Total | C5: Final Total | D5: Q1 Points | E5: Q2 Points | F5: Game Total | H5: 2PM | I5: 2PA | J5: 3PM | K5: 3PA | L5: FGM | M5: FGA | N5: FTM | O5: FTA | P5: DREB | Q5: OREB | R5: AST | S5: TO | T5: STL | U5: BLK
A6: Our Team | B6: 12 | C6: 33 | D6: =IF(B6="","",B6) -> 12 | E6: =IF(OR(B6="",C6=""),"",C6-B6) -> 21 | F6: =IF(C6="","",C6) -> 33 | H6: =SUM(D10:D30) -> 6 | I6: =SUM(E10:E30) -> 30 | J6: =SUM(F10:F30) -> 5 | K6: =SUM(G10:G30) -> 25 | L6: =SUM(D10:D30)+SUM(F10:F30) -> 11 | M6: =SUM(E10:E30)+SUM(G10:G30) -> 55 | N6: =SUM(H10:H30) -> 6 | O6: =SUM(I11:I30) -> 18 | P6: =SUM(J11:J30) -> 19 | Q6: =SUM(K11:K30) -> 13 | R6: =SUM(L11:L30) -> 7 | S6: =SUM(M11:M30) -> 10 | T6: =SUM(N11:N30) -> 11 | U6: =SUM(O11:O30) -> 2
A7: Opponent | B7: 17 | C7: 38 | D7: =IF(B7="","",B7) -> 17 | E7: =IF(OR(B7="",C7=""),"",C7-B7) -> 21 | F7: =IF(C7="","",C7) -> 38 | H7: 2P% | I7: =H6/I6 -> 0.2 | J7: 3P% | K7: =J6/K6 -> 0.2 | L7: FG% | M7: =L6/M6 -> 0.2 | N7: FT% | O7: =N6/O6 -> 0.33333333
A9: Player Stat Entry | B9: Player Stat Entry | C9: Player Stat Entry | D9: Player Stat Entry | E9: Player Stat Entry | F9: Player Stat Entry | G9: Player Stat Entry | H9: Player Stat Entry | I9: Player Stat Entry | J9: Player Stat Entry | K9: Player Stat Entry | L9: Player Stat Entry | M9: Player Stat Entry | O9: Player Stat Entry | P9: Player Stat Entry | Q9: Player Stat Entry | R9: Player Stat Entry | S9: Player Stat Entry | T9: Player Stat Entry
A10: Slot | B10: Jersey # | C10: Player | D10: 2PM | E10: 2PA | F10: 3PM | G10: 3PA | H10: FTM | I10: FTA | J10: DREB | K10: OREB | L10: AST | M10: TrnOv | N10: STL | O10: BLK | P10: FGM | Q10: FGA | R10: PTS | S10: FG% | T10: FT%
A11: 1 | B11: =IF(Roster!B5="","",Roster!B5) | C11: =IF(Roster!C5="","",Roster!C5) -> Brendan Wong | P11: =IF(SUM(D11,F11)=0,"",D11+F11) | Q11: =IF(SUM(E11,G11)=0,"",E11+G11) | R11: =IF(SUM(D11,F11,H11)=0,"",D11*2+F11*3+H11) | S11: =IF(Q11="","",IF(P11="",0,P11/Q11)) | T11: =IF(I11=0,"",H11/I11)
A12: 2 | B12: =IF(Roster!B6="","",Roster!B6) | C12: =IF(Roster!C6="","",Roster!C6) -> Kevin Chen | D12: 2 | E12: 9 | F12: 0 | G12: 3 | H12: 3 | I12: 13 | J12: 4 | K12: 1 | L12: 2 | M12: 3 | N12: 2 | O12: 0 | P12: =IF(SUM(D12,F12)=0,"",D12+F12) -> 2 | Q12: =IF(SUM(E12,G12)=0,"",E12+G12) -> 12 | R12: =IF(SUM(D12,F12,H12)=0,"",D12*2+F12*3+H12) -> 7 | S12: =IF(Q12="","",IF(P12="",0,P12/Q12)) -> 0.16666667 | T12: =IF(I12=0,"",H12/I12) -> 0.23076923
A13: 3 | B13: =IF(Roster!B7="","",Roster!B7) | C13: =IF(Roster!C7="","",Roster!C7) -> Siddarth D | D13: 2 | E13: 4 | F13: 0 | G13: 1 | H13: 0 | I13: 0 | J13: 6 | K13: 3 | L13: 0 | M13: 2 | N13: 3 | O13: 2 | P13: =IF(SUM(D13,F13)=0,"",D13+F13) -> 2 | Q13: =IF(SUM(E13,G13)=0,"",E13+G13) -> 5 | R13: =IF(SUM(D13,F13,H13)=0,"",D13*2+F13*3+H13) -> 4 | S13: =IF(Q13="","",IF(P13="",0,P13/Q13)) -> 0.4 | T13: =IF(I13=0,"",H13/I13)
A14: 4 | B14: =IF(Roster!B8="","",Roster!B8) | C14: =IF(Roster!C8="","",Roster!C8) -> Ethan Hu | D14: 0 | E14: 3 | F14: 1 | G14: 6 | H14: 1 | I14: 2 | J14: 3 | K14: 3 | L14: 1 | M14: 0 | N14: 0 | O14: 0 | P14: =IF(SUM(D14,F14)=0,"",D14+F14) -> 1 | Q14: =IF(SUM(E14,G14)=0,"",E14+G14) -> 9 | R14: =IF(SUM(D14,F14,H14)=0,"",D14*2+F14*3+H14) -> 4 | S14: =IF(Q14="","",IF(P14="",0,P14/Q14)) -> 0.11111111 | T14: =IF(I14=0,"",H14/I14) -> 0.5
A15: 5 | B15: =IF(Roster!B9="","",Roster!B9) | C15: =IF(Roster!C9="","",Roster!C9) -> Kenny Liou | D15: 1 | E15: 2 | F15: 0 | G15: 0 | H15: 2 | I15: 3 | J15: 3 | K15: 5 | L15: 2 | M15: 1 | N15: 2 | O15: 0 | P15: =IF(SUM(D15,F15)=0,"",D15+F15) -> 1 | Q15: =IF(SUM(E15,G15)=0,"",E15+G15) -> 2 | R15: =IF(SUM(D15,F15,H15)=0,"",D15*2+F15*3+H15) -> 4 | S15: =IF(Q15="","",IF(P15="",0,P15/Q15)) -> 0.5 | T15: =IF(I15=0,"",H15/I15) -> 0.66666667
A16: 6 | B16: =IF(Roster!B10="","",Roster!B10) | C16: =IF(Roster!C10="","",Roster!C10) -> Max Lee | P16: =IF(SUM(D16,F16)=0,"",D16+F16) | Q16: =IF(SUM(E16,G16)=0,"",E16+G16) | R16: =IF(SUM(D16,F16,H16)=0,"",D16*2+F16*3+H16) | S16: =IF(Q16="","",IF(P16="",0,P16/Q16)) | T16: =IF(I16=0,"",H16/I16)
A17: 7 | B17: =IF(Roster!B11="","",Roster!B11) | C17: =IF(Roster!C11="","",Roster!C11) -> Xuanyi W | P17: =IF(SUM(D17,F17)=0,"",D17+F17) | Q17: =IF(SUM(E17,G17)=0,"",E17+G17) | R17: =IF(SUM(D17,F17,H17)=0,"",D17*2+F17*3+H17) | S17: =IF(Q17="","",IF(P17="",0,P17/Q17)) | T17: =IF(I17=0,"",H17/I17)
A18: 8 | B18: =IF(Roster!B12="","",Roster!B12) | C18: =IF(Roster!C12="","",Roster!C12) -> Markus Wong | D18: 0 | E18: 0 | F18: 0 | G18: 0 | H18: 0 | I18: 0 | J18: 0 | K18: 0 | L18: 0 | M18: 0 | N18: 0 | O18: 0 | P18: =IF(SUM(D18,F18)=0,"",D18+F18) | Q18: =IF(SUM(E18,G18)=0,"",E18+G18) | R18: =IF(SUM(D18,F18,H18)=0,"",D18*2+F18*3+H18) | S18: =IF(Q18="","",IF(P18="",0,P18/Q18)) | T18: =IF(I18=0,"",H18/I18)
A19: 9 | B19: =IF(Roster!B13="","",Roster!B13) | C19: =IF(Roster!C13="","",Roster!C13) -> Thomas N | D19: 0 | E19: 2 | F19: 1 | G19: 1 | H19: 0 | I19: 0 | J19: 0 | K19: 1 | L19: 1 | M19: 0 | N19: 0 | O19: 0 | P19: =IF(SUM(D19,F19)=0,"",D19+F19) -> 1 | Q19: =IF(SUM(E19,G19)=0,"",E19+G19) -> 3 | R19: =IF(SUM(D19,F19,H19)=0,"",D19*2+F19*3+H19) -> 3 | S19: =IF(Q19="","",IF(P19="",0,P19/Q19)) -> 0.33333333 | T19: =IF(I19=0,"",H19/I19)
A20: 10 | B20: =IF(Roster!B14="","",Roster!B14) | C20: =IF(Roster!C14="","",Roster!C14) -> Arjun V | D20: 1 | E20: 9 | F20: 3 | G20: 12 | H20: 0 | I20: 0 | J20: 1 | K20: 0 | L20: 1 | M20: 4 | N20: 3 | O20: 0 | P20: =IF(SUM(D20,F20)=0,"",D20+F20) -> 4 | Q20: =IF(SUM(E20,G20)=0,"",E20+G20) -> 21 | R20: =IF(SUM(D20,F20,H20)=0,"",D20*2+F20*3+H20) -> 11 | S20: =IF(Q20="","",IF(P20="",0,P20/Q20)) -> 0.19047619 | T20: =IF(I20=0,"",H20/I20)
A21: 11 | B21: =IF(Roster!B15="","",Roster!B15) | C21: =IF(Roster!C15="","",Roster!C15) -> Yash S | P21: =IF(SUM(D21,F21)=0,"",D21+F21) | Q21: =IF(SUM(E21,G21)=0,"",E21+G21) | R21: =IF(SUM(D21,F21,H21)=0,"",D21*2+F21*3+H21) | S21: =IF(Q21="","",IF(P21="",0,P21/Q21)) | T21: =IF(I21=0,"",H21/I21)
A22: 12 | B22: =IF(Roster!B16="","",Roster!B16) | C22: =IF(Roster!C16="","",Roster!C16) -> Will | D22: 0 | E22: 1 | F22: 0 | G22: 1 | H22: 0 | I22: 0 | J22: 2 | K22: 0 | L22: 0 | M22: 0 | N22: 1 | O22: 0 | P22: =IF(SUM(D22,F22)=0,"",D22+F22) | Q22: =IF(SUM(E22,G22)=0,"",E22+G22) -> 2 | R22: =IF(SUM(D22,F22,H22)=0,"",D22*2+F22*3+H22) | S22: =IF(Q22="","",IF(P22="",0,P22/Q22)) -> 0 | T22: =IF(I22=0,"",H22/I22)
A23: 13 | B23: =IF(Roster!B17="","",Roster!B17) | C23: =IF(Roster!C17="","",Roster!C17) -> Steven | D23: 0 | E23: 0 | F23: 0 | G23: 1 | H23: 0 | I23: 0 | J23: 0 | K23: 0 | L23: 0 | M23: 0 | N23: 0 | O23: 0 | P23: =IF(SUM(D23,F23)=0,"",D23+F23) | Q23: =IF(SUM(E23,G23)=0,"",E23+G23) -> 1 | R23: =IF(SUM(D23,F23,H23)=0,"",D23*2+F23*3+H23) | S23: =IF(Q23="","",IF(P23="",0,P23/Q23)) -> 0 | T23: =IF(I23=0,"",H23/I23)
A24: 14 | B24: =IF(Roster!B18="","",Roster!B18) | C24: =IF(Roster!C18="","",Roster!C18) -> Vee | P24: =IF(SUM(D24,F24)=0,"",D24+F24) | Q24: =IF(SUM(E24,G24)=0,"",E24+G24) | R24: =IF(SUM(D24,F24,H24)=0,"",D24*2+F24*3+H24) | S24: =IF(Q24="","",IF(P24="",0,P24/Q24)) | T24: =IF(I24=0,"",H24/I24)
A25: 15 | B25: =IF(Roster!B19="","",Roster!B19) | C25: =IF(Roster!C19="","",Roster!C19) -> Michael | P25: =IF(SUM(D25,F25)=0,"",D25+F25) | Q25: =IF(SUM(E25,G25)=0,"",E25+G25) | R25: =IF(SUM(D25,F25,H25)=0,"",D25*2+F25*3+H25) | S25: =IF(Q25="","",IF(P25="",0,P25/Q25)) | T25: =IF(I25=0,"",H25/I25)
A26: 16 | B26: =IF(Roster!B20="","",Roster!B20) | C26: =IF(Roster!C20="","",Roster!C20) -> Eddie | P26: =IF(SUM(D26,F26)=0,"",D26+F26) | Q26: =IF(SUM(E26,G26)=0,"",E26+G26) | R26: =IF(SUM(D26,F26,H26)=0,"",D26*2+F26*3+H26) | S26: =IF(Q26="","",IF(P26="",0,P26/Q26)) | T26: =IF(I26=0,"",H26/I26)
A27: 17 | B27: =IF(Roster!B21="","",Roster!B21) | C27: =IF(Roster!C21="","",Roster!C21) -> Stephen Zhong | P27: =IF(SUM(D27,F27)=0,"",D27+F27) | Q27: =IF(SUM(E27,G27)=0,"",E27+G27) | R27: =IF(SUM(D27,F27,H27)=0,"",D27*2+F27*3+H27) | S27: =IF(Q27="","",IF(P27="",0,P27/Q27)) | T27: =IF(I27=0,"",H27/I27)
A28: 18 | B28: =IF(Roster!B22="","",Roster!B22) | C28: =IF(Roster!C22="","",Roster!C22) | P28: =IF(SUM(D28,F28)=0,"",D28+F28) | Q28: =IF(SUM(E28,G28)=0,"",E28+G28) | R28: =IF(SUM(D28,F28,H28)=0,"",D28*2+F28*3+H28) | S28: =IF(Q28="","",IF(P28="",0,P28/Q28)) | T28: =IF(I28=0,"",H28/I28)
A29: 19 | B29: =IF(Roster!B23="","",Roster!B23) | C29: =IF(Roster!C23="","",Roster!C23) | P29: =IF(SUM(D29,F29)=0,"",D29+F29) | Q29: =IF(SUM(E29,G29)=0,"",E29+G29) | R29: =IF(SUM(D29,F29,H29)=0,"",D29*2+F29*3+H29) | S29: =IF(Q29="","",IF(P29="",0,P29/Q29)) | T29: =IF(I29=0,"",H29/I29)
A30: 20 | B30: =IF(Roster!B24="","",Roster!B24) | C30: =IF(Roster!C24="","",Roster!C24) | P30: =IF(SUM(D30,F30)=0,"",D30+F30) | Q30: =IF(SUM(E30,G30)=0,"",E30+G30) | R30: =IF(SUM(D30,F30,H30)=0,"",D30*2+F30*3+H30) | S30: =IF(Q30="","",IF(P30="",0,P30/Q30)) | T30: =IF(I30=0,"",H30/I30)

Sheet Game 3 Stats Sheet
A1: Live Game Sheet | B1: Live Game Sheet | C1: Live Game Sheet | D1: Live Game Sheet | E1: Live Game Sheet | F1: Live Game Sheet | G1: Live Game Sheet | H1: Live Game Sheet | I1: Live Game Sheet | J1: Live Game Sheet | K1: Live Game Sheet | L1: Live Game Sheet | M1: Live Game Sheet | O1: Live Game Sheet | P1: Live Game Sheet | Q1: Live Game Sheet | R1: Live Game Sheet | S1: Live Game Sheet | T1: Live Game Sheet
A2: Game Date | B2: 46237 | D2: Opponent | E2: Blue | G2: Location | H2: Telegraph Hill Community Center
A4: Score: Enter Total Score At End Of Quarter | B4: Score: Enter Total Score At End Of Quarter | C4: Score: Enter Total Score At End Of Quarter | D4: Score: Enter Total Score At End Of Quarter | E4: Score: Enter Total Score At End Of Quarter | F4: Score: Enter Total Score At End Of Quarter | H4: Team Totals From Player Stats
A5: Team | B5: Q1 End Total | C5: Final Total | D5: Q1 Points | E5: Q2 Points | F5: Game Total | H5: 2PM | I5: 2PA | J5: 3PM | K5: 3PA | L5: FGM | M5: FGA | N5: FTM | O5: FTA | P5: DREB | Q5: OREB | R5: AST | S5: TO | T5: STL | U5: BLK
A6: Our Team | B6: 20 | C6: 41 | D6: =IF(B6="","",B6) -> 20 | E6: =IF(OR(B6="",C6=""),"",C6-B6) -> 21 | F6: =IF(C6="","",C6) -> 41 | H6: =SUM(D10:D30) -> 12 | I6: =SUM(E10:E30) -> 34 | J6: =SUM(F10:F30) -> 4 | K6: =SUM(G10:G30) -> 21 | L6: =SUM(D10:D30)+SUM(F10:F30) -> 16 | M6: =SUM(E10:E30)+SUM(G10:G30) -> 55 | N6: =SUM(H10:H30) -> 5 | O6: =SUM(I10:I30) -> 12 | P6: =SUM(J10:J30) -> 33 | Q6: =SUM(K10:K30) -> 11 | R6: =SUM(L10:L30) -> 6 | S6: =SUM(M10:M30) -> 20 | T6: =SUM(N10:N30) -> 6 | U6: =SUM(O10:O30) -> 6
A7: Opponent | B7: 21 | C7: 38 | D7: =IF(B7="","",B7) -> 21 | E7: =IF(OR(B7="",C7=""),"",C7-B7) -> 17 | F7: =IF(C7="","",C7) -> 38 | H7: 2P% | I7: =H6/I6 -> 0.35294118 | J7: 3P% | K7: =J6/K6 -> 0.19047619 | L7: FG% | M7: =L6/M6 -> 0.29090909 | N7: FT% | O7: =N6/O6 -> 0.41666667
A9: Player Stat Entry | B9: Player Stat Entry | C9: Player Stat Entry | D9: Player Stat Entry | E9: Player Stat Entry | F9: Player Stat Entry | G9: Player Stat Entry | H9: Player Stat Entry | I9: Player Stat Entry | J9: Player Stat Entry | K9: Player Stat Entry | L9: Player Stat Entry | M9: Player Stat Entry | O9: Player Stat Entry | P9: Player Stat Entry | Q9: Player Stat Entry | R9: Player Stat Entry | S9: Player Stat Entry | T9: Player Stat Entry
A10: Slot | B10: Jersey # | C10: Player | D10: 2PM | E10: 2PA | F10: 3PM | G10: 3PA | H10: FTM | I10: FTA | J10: DREB | K10: OREB | L10: AST | M10: TrnOv | N10: STL | O10: BLK | P10: FGM | Q10: FGA | R10: PTS | S10: FG% | T10: FT%
A11: 1 | B11: =IF(Roster!B5="","",Roster!B5) | C11: =IF(Roster!C5="","",Roster!C5) -> Brendan Wong | D11: 5 | E11: 11 | F11: 0 | G11: 6 | H11: 1 | I11: 5 | J11: 4 | K11: 0 | L11: 3 | M11: 3 | N11: 1 | O11: 0 | P11: =IF(SUM(D11,F11)=0,"",D11+F11) -> 5 | Q11: =IF(SUM(E11,G11)=0,"",E11+G11) -> 17 | R11: =IF(SUM(D11,F11,H11)=0,"",D11*2+F11*3+H11) -> 11 | S11: =IF(Q11="","",IF(P11="",0,P11/Q11)) -> 0.29411765 | T11: =IF(I11=0,"",H11/I11) -> 0.2
A12: 2 | B12: =IF(Roster!B6="","",Roster!B6) | C12: =IF(Roster!C6="","",Roster!C6) -> Kevin Chen | P12: =IF(SUM(D12,F12)=0,"",D12+F12) | Q12: =IF(SUM(E12,G12)=0,"",E12+G12) | R12: =IF(SUM(D12,F12,H12)=0,"",D12*2+F12*3+H12) | S12: =IF(Q12="","",IF(P12="",0,P12/Q12)) | T12: =IF(I12=0,"",H12/I12)
A13: 3 | B13: =IF(Roster!B7="","",Roster!B7) | C13: =IF(Roster!C7="","",Roster!C7) -> Siddarth D | D13: 1 | E13: 3 | F13: 0 | G13: 0 | H13: 1 | I13: 2 | J13: 4 | K13: 3 | L13: 0 | M13: 6 | N13: 3 | O13: 4 | P13: =IF(SUM(D13,F13)=0,"",D13+F13) -> 1 | Q13: =IF(SUM(E13,G13)=0,"",E13+G13) -> 3 | R13: =IF(SUM(D13,F13,H13)=0,"",D13*2+F13*3+H13) -> 3 | S13: =IF(Q13="","",IF(P13="",0,P13/Q13)) -> 0.33333333 | T13: =IF(I13=0,"",H13/I13) -> 0.5
A14: 4 | B14: =IF(Roster!B8="","",Roster!B8) | C14: =IF(Roster!C8="","",Roster!C8) -> Ethan Hu | D14: 0 | E14: 0 | F14: 0 | G14: 1 | H14: 0 | I14: 0 | J14: 3 | K14: 0 | L14: 0 | M14: 3 | N14: 0 | O14: 0 | P14: =IF(SUM(D14,F14)=0,"",D14+F14) | Q14: =IF(SUM(E14,G14)=0,"",E14+G14) -> 1 | R14: =IF(SUM(D14,F14,H14)=0,"",D14*2+F14*3+H14) | S14: =IF(Q14="","",IF(P14="",0,P14/Q14)) -> 0 | T14: =IF(I14=0,"",H14/I14)
A15: 5 | B15: =IF(Roster!B9="","",Roster!B9) | C15: =IF(Roster!C9="","",Roster!C9) -> Kenny Liou | P15: =IF(SUM(D15,F15)=0,"",D15+F15) | Q15: =IF(SUM(E15,G15)=0,"",E15+G15) | R15: =IF(SUM(D15,F15,H15)=0,"",D15*2+F15*3+H15) | S15: =IF(Q15="","",IF(P15="",0,P15/Q15)) | T15: =IF(I15=0,"",H15/I15)
A16: 6 | B16: =IF(Roster!B10="","",Roster!B10) | C16: =IF(Roster!C10="","",Roster!C10) -> Max Lee | D16: 0 | E16: 1 | F16: 0 | G16: 3 | H16: 0 | I16: 0 | J16: 3 | K16: 2 | L16: 1 | M16: 2 | N16: 1 | O16: 0 | P16: =IF(SUM(D16,F16)=0,"",D16+F16) | Q16: =IF(SUM(E16,G16)=0,"",E16+G16) -> 4 | R16: =IF(SUM(D16,F16,H16)=0,"",D16*2+F16*3+H16) | S16: =IF(Q16="","",IF(P16="",0,P16/Q16)) -> 0 | T16: =IF(I16=0,"",H16/I16)
A17: 7 | B17: =IF(Roster!B11="","",Roster!B11) | C17: =IF(Roster!C11="","",Roster!C11) -> Xuanyi W | D17: 0 | E17: 1 | F17: 0 | G17: 0 | H17: 0 | I17: 0 | J17: 0 | K17: 0 | L17: 0 | M17: 0 | N17: 0 | O17: 0 | P17: =IF(SUM(D17,F17)=0,"",D17+F17) | Q17: =IF(SUM(E17,G17)=0,"",E17+G17) -> 1 | R17: =IF(SUM(D17,F17,H17)=0,"",D17*2+F17*3+H17) | S17: =IF(Q17="","",IF(P17="",0,P17/Q17)) -> 0 | T17: =IF(I17=0,"",H17/I17)
A18: 8 | B18: =IF(Roster!B12="","",Roster!B12) | C18: =IF(Roster!C12="","",Roster!C12) -> Markus Wong | D18: 0 | E18: 0 | F18: 0 | G18: 0 | H18: 0 | I18: 0 | J18: 0 | K18: 0 | L18: 0 | M18: 1 | N18: 0 | O18: 0 | P18: =IF(SUM(D18,F18)=0,"",D18+F18) | Q18: =IF(SUM(E18,G18)=0,"",E18+G18) | R18: =IF(SUM(D18,F18,H18)=0,"",D18*2+F18*3+H18) | S18: =IF(Q18="","",IF(P18="",0,P18/Q18)) | T18: =IF(I18=0,"",H18/I18)
A19: 9 | B19: =IF(Roster!B13="","",Roster!B13) | C19: =IF(Roster!C13="","",Roster!C13) -> Thomas N | D19: 0 | E19: 2 | F19: 0 | G19: 2 | H19: 0 | I19: 0 | J19: 0 | K19: 1 | L19: 0 | M19: 0 | N19: 0 | O19: 0 | P19: =IF(SUM(D19,F19)=0,"",D19+F19) | Q19: =IF(SUM(E19,G19)=0,"",E19+G19) -> 4 | R19: =IF(SUM(D19,F19,H19)=0,"",D19*2+F19*3+H19) | S19: =IF(Q19="","",IF(P19="",0,P19/Q19)) -> 0 | T19: =IF(I19=0,"",H19/I19)
A20: 10 | B20: =IF(Roster!B14="","",Roster!B14) | C20: =IF(Roster!C14="","",Roster!C14) -> Arjun V | D20: 2 | E20: 6 | F20: 4 | G20: 6 | H20: 2 | I20: 2 | J20: 4 | K20: 1 | L20: 1 | M20: 3 | N20: 0 | O20: 1 | P20: =IF(SUM(D20,F20)=0,"",D20+F20) -> 6 | Q20: =IF(SUM(E20,G20)=0,"",E20+G20) -> 12 | R20: =IF(SUM(D20,F20,H20)=0,"",D20*2+F20*3+H20) -> 18 | S20: =IF(Q20="","",IF(P20="",0,P20/Q20)) -> 0.5 | T20: =IF(I20=0,"",H20/I20) -> 1
A21: 11 | B21: =IF(Roster!B15="","",Roster!B15) | C21: =IF(Roster!C15="","",Roster!C15) -> Yash S | D21: 3 | E21: 5 | F21: 0 | G21: 0 | H21: 0 | I21: 0 | J21: 1 | K21: 0 | L21: 0 | M21: 0 | N21: 1 | O21: 1 | P21: =IF(SUM(D21,F21)=0,"",D21+F21) -> 3 | Q21: =IF(SUM(E21,G21)=0,"",E21+G21) -> 5 | R21: =IF(SUM(D21,F21,H21)=0,"",D21*2+F21*3+H21) -> 6 | S21: =IF(Q21="","",IF(P21="",0,P21/Q21)) -> 0.6 | T21: =IF(I21=0,"",H21/I21)
A22: 12 | B22: =IF(Roster!B16="","",Roster!B16) | C22: =IF(Roster!C16="","",Roster!C16) -> Will | D22: 0 | E22: 1 | F22: 0 | G22: 1 | H22: 0 | I22: 0 | J22: 4 | K22: 0 | L22: 0 | M22: 1 | N22: 0 | O22: 0 | P22: =IF(SUM(D22,F22)=0,"",D22+F22) | Q22: =IF(SUM(E22,G22)=0,"",E22+G22) -> 2 | R22: =IF(SUM(D22,F22,H22)=0,"",D22*2+F22*3+H22) | S22: =IF(Q22="","",IF(P22="",0,P22/Q22)) -> 0 | T22: =IF(I22=0,"",H22/I22)
A23: 13 | B23: =IF(Roster!B17="","",Roster!B17) | C23: =IF(Roster!C17="","",Roster!C17) -> Steven | D23: 0 | E23: 0 | F23: 0 | G23: 1 | H23: 0 | I23: 0 | J23: 1 | K23: 1 | L23: 0 | M23: 0 | N23: 0 | O23: 0 | P23: =IF(SUM(D23,F23)=0,"",D23+F23) | Q23: =IF(SUM(E23,G23)=0,"",E23+G23) -> 1 | R23: =IF(SUM(D23,F23,H23)=0,"",D23*2+F23*3+H23) | S23: =IF(Q23="","",IF(P23="",0,P23/Q23)) -> 0 | T23: =IF(I23=0,"",H23/I23)
A24: 14 | B24: =IF(Roster!B18="","",Roster!B18) | C24: =IF(Roster!C18="","",Roster!C18) -> Vee | D24: 1 | E24: 4 | F24: 0 | G24: 1 | H24: 1 | I24: 3 | J24: 9 | K24: 3 | L24: 1 | M24: 1 | N24: 0 | O24: 0 | P24: =IF(SUM(D24,F24)=0,"",D24+F24) -> 1 | Q24: =IF(SUM(E24,G24)=0,"",E24+G24) -> 5 | R24: =IF(SUM(D24,F24,H24)=0,"",D24*2+F24*3+H24) -> 3 | S24: =IF(Q24="","",IF(P24="",0,P24/Q24)) -> 0.2 | T24: =IF(I24=0,"",H24/I24) -> 0.33333333
A25: 15 | B25: =IF(Roster!B19="","",Roster!B19) | C25: =IF(Roster!C19="","",Roster!C19) -> Michael | P25: =IF(SUM(D25,F25)=0,"",D25+F25) | Q25: =IF(SUM(E25,G25)=0,"",E25+G25) | R25: =IF(SUM(D25,F25,H25)=0,"",D25*2+F25*3+H25) | S25: =IF(Q25="","",IF(P25="",0,P25/Q25)) | T25: =IF(I25=0,"",H25/I25)
A26: 16 | B26: =IF(Roster!B20="","",Roster!B20) | C26: =IF(Roster!C20="","",Roster!C20) -> Eddie | P26: =IF(SUM(D26,F26)=0,"",D26+F26) | Q26: =IF(SUM(E26,G26)=0,"",E26+G26) | R26: =IF(SUM(D26,F26,H26)=0,"",D26*2+F26*3+H26) | S26: =IF(Q26="","",IF(P26="",0,P26/Q26)) | T26: =IF(I26=0,"",H26/I26)
A27: 17 | B27: =IF(Roster!B21="","",Roster!B21) | C27: =IF(Roster!C21="","",Roster!C21) -> Stephen Zhong | P27: =IF(SUM(D27,F27)=0,"",D27+F27) | Q27: =IF(SUM(E27,G27)=0,"",E27+G27) | R27: =IF(SUM(D27,F27,H27)=0,"",D27*2+F27*3+H27) | S27: =IF(Q27="","",IF(P27="",0,P27/Q27)) | T27: =IF(I27=0,"",H27/I27)
A28: 18 | B28: =IF(Roster!B22="","",Roster!B22) | C28: =IF(Roster!C22="","",Roster!C22) | P28: =IF(SUM(D28,F28)=0,"",D28+F28) | Q28: =IF(SUM(E28,G28)=0,"",E28+G28) | R28: =IF(SUM(D28,F28,H28)=0,"",D28*2+F28*3+H28) | S28: =IF(Q28="","",IF(P28="",0,P28/Q28)) | T28: =IF(I28=0,"",H28/I28)
A29: 19 | B29: =IF(Roster!B23="","",Roster!B23) | C29: =IF(Roster!C23="","",Roster!C23) | P29: =IF(SUM(D29,F29)=0,"",D29+F29) | Q29: =IF(SUM(E29,G29)=0,"",E29+G29) | R29: =IF(SUM(D29,F29,H29)=0,"",D29*2+F29*3+H29) | S29: =IF(Q29="","",IF(P29="",0,P29/Q29)) | T29: =IF(I29=0,"",H29/I29)
A30: 20 | B30: =IF(Roster!B24="","",Roster!B24) | C30: =IF(Roster!C24="","",Roster!C24) | P30: =IF(SUM(D30,F30)=0,"",D30+F30) | Q30: =IF(SUM(E30,G30)=0,"",E30+G30) | R30: =IF(SUM(D30,F30,H30)=0,"",D30*2+F30*3+H30) | S30: =IF(Q30="","",IF(P30="",0,P30/Q30)) | T30: =IF(I30=0,"",H30/I30)

Sheet Player Game Log
A1: Player Game Log | B1: Player Game Log | C1: Player Game Log | D1: Player Game Log | E1: Player Game Log | F1: Player Game Log | G1: Player Game Log | H1: Player Game Log | I1: Player Game Log | J1: Player Game Log | K1: Player Game Log | L1: Player Game Log | M1: Player Game Log | N1: Player Game Log | O1: Player Game Log | P1: Player Game Log | Q1: Player Game Log | S1: Player Game Log | T1: Player Game Log | U1: Player Game Log
A3: Game ID | B3: Date | C3: Opponent | D3: Jersey # | E3: Player | F3: 2PM | G3: 2PA | H3: 3PM | I3: 3PA | J3: FTM | K3: FTA | L3: DREB | M3: OREB | N3: AST | O3: TO | P3: STL | Q3: BLK | R3: FGM | S3: FGA | T3: PTS | U3: FG% | V3: FT%
A4: 1 | B4: 46223 | C4: White | E4: Kevin Chen | F4: 5 | G4: 14 | H4: 1 | I4: 2 | J4: 2 | K4: 8 | L4: 6 | M4: 0 | N4: 1 | O4: 2 | P4: 1 | R4: =IF(AND(F4="",H4=""),"",IF(SUM(F4,H4)=0,0,F4+H4)) -> 6 | S4: =IF(SUM(G4,I4)=0,"",G4+I4) -> 16 | T4: =IF(SUM(F4,H4,J4)=0,"",F4*2+H4*3+J4) -> 15 | U4: =IF(S4="","",IF(R4="",0,R4/S4)) -> 0.375 | V4: =IF(K4=0,"",J4/K4) -> 0.25
A5: 1 | B5: 46223 | C5: White | E5: Ethan Hu | F5: 0 | G5: 1 | H5: 0 | I5: 4 | J5: 0 | K5: 0 | L5: 2 | M5: 0 | N5: 0 | O5: 1 | P5: 0 | R5: =IF(AND(F5="",H5=""),"",IF(SUM(F5,H5)=0,0,F5+H5)) -> 0 | S5: =IF(SUM(G5,I5)=0,"",G5+I5) -> 5 | T5: =IF(SUM(F5,H5,J5)=0,"",F5*2+H5*3+J5) | U5: =IF(S5="","",IF(R5="",0,R5/S5)) -> 0 | V5: =IF(K5=0,"",J5/K5)
A6: 1 | B6: 46223 | C6: White | E6: Kenny Liou | F6: 0 | G6: 3 | H6: 0 | I6: 1 | J6: 0 | K6: 0 | L6: 5 | M6: 1 | N6: 0 | O6: 0 | P6: 1 | R6: =IF(AND(F6="",H6=""),"",IF(SUM(F6,H6)=0,0,F6+H6)) -> 0 | S6: =IF(SUM(G6,I6)=0,"",G6+I6) -> 4 | T6: =IF(SUM(F6,H6,J6)=0,"",F6*2+H6*3+J6) | U6: =IF(S6="","",IF(R6="",0,R6/S6)) -> 0 | V6: =IF(K6=0,"",J6/K6)
A7: 1 | B7: 46223 | C7: White | E7: Max Lee | F7: 0 | G7: 0 | H7: 0 | I7: 7 | J7: 0 | K7: 0 | L7: 2 | M7: 1 | N7: 0 | O7: 0 | P7: 0 | R7: =IF(AND(F7="",H7=""),"",IF(SUM(F7,H7)=0,0,F7+H7)) -> 0 | S7: =IF(SUM(G7,I7)=0,"",G7+I7) -> 7 | T7: =IF(SUM(F7,H7,J7)=0,"",F7*2+H7*3+J7) | U7: =IF(S7="","",IF(R7="",0,R7/S7)) -> 0 | V7: =IF(K7=0,"",J7/K7)
A8: 1 | B8: 46223 | C8: White | E8: Xuanyi W | F8: 1 | G8: 1 | H8: 1 | I8: 3 | J8: 0 | K8: 0 | L8: 4 | M8: 1 | N8: 0 | O8: 0 | P8: 1 | R8: =IF(AND(F8="",H8=""),"",IF(SUM(F8,H8)=0,0,F8+H8)) -> 2 | S8: =IF(SUM(G8,I8)=0,"",G8+I8) -> 4 | T8: =IF(SUM(F8,H8,J8)=0,"",F8*2+H8*3+J8) -> 5 | U8: =IF(S8="","",IF(R8="",0,R8/S8)) -> 0.5 | V8: =IF(K8=0,"",J8/K8)
A9: 1 | B9: 46223 | C9: White | E9: Markus Wong | F9: 0 | G9: 2 | H9: 0 | I9: 0 | J9: 0 | K9: 0 | L9: 0 | M9: 0 | N9: 0 | O9: 0 | P9: 0 | R9: =IF(AND(F9="",H9=""),"",IF(SUM(F9,H9)=0,0,F9+H9)) -> 0 | S9: =IF(SUM(G9,I9)=0,"",G9+I9) -> 2 | T9: =IF(SUM(F9,H9,J9)=0,"",F9*2+H9*3+J9) | U9: =IF(S9="","",IF(R9="",0,R9/S9)) -> 0 | V9: =IF(K9=0,"",J9/K9)
A10: 1 | B10: 46223 | C10: White | E10: Thomas N | F10: 0 | G10: 0 | H10: 0 | I10: 3 | J10: 0 | K10: 0 | L10: 1 | M10: 0 | N10: 0 | O10: 0 | P10: 0 | R10: =IF(AND(F10="",H10=""),"",IF(SUM(F10,H10)=0,0,F10+H10)) -> 0 | S10: =IF(SUM(G10,I10)=0,"",G10+I10) -> 3 | T10: =IF(SUM(F10,H10,J10)=0,"",F10*2+H10*3+J10) | U10: =IF(S10="","",IF(R10="",0,R10/S10)) -> 0 | V10: =IF(K10=0,"",J10/K10)
A11: 1 | B11: 46223 | C11: White | E11: Arjun V | F11: 4 | G11: 9 | H11: 0 | I11: 10 | J11: 3 | K11: 3 | L11: 4 | M11: 0 | N11: 1 | O11: 1 | P11: 1 | R11: =IF(AND(F11="",H11=""),"",IF(SUM(F11,H11)=0,0,F11+H11)) -> 4 | S11: =IF(SUM(G11,I11)=0,"",G11+I11) -> 19 | T11: =IF(SUM(F11,H11,J11)=0,"",F11*2+H11*3+J11) -> 11 | U11: =IF(S11="","",IF(R11="",0,R11/S11)) -> 0.21052632 | V11: =IF(K11=0,"",J11/K11) -> 1
A12: 2 | B12: 46230 | C12: Green | E12: Kevin Chen | F12: 2 | G12: 9 | H12: 0 | I12: 3 | J12: 3 | K12: 13 | L12: 4 | M12: 1 | N12: 2 | O12: 3 | P12: 2 | Q12: 0 | R12: =IF(AND(F12="",H12=""),"",IF(SUM(F12,H12)=0,0,F12+H12)) -> 2 | S12: =IF(SUM(G12,I12)=0,"",G12+I12) -> 12 | T12: =IF(SUM(F12,H12,J12)=0,"",F12*2+H12*3+J12) -> 7 | U12: =IF(S12="","",IF(R12="",0,R12/S12)) -> 0.16666667 | V12: =IF(K12=0,"",J12/K12) -> 0.23076923
A13: 2 | B13: 46230 | C13: Green | E13: Siddarth D | F13: 2 | G13: 4 | H13: 0 | I13: 1 | J13: 0 | K13: 0 | L13: 6 | M13: 3 | N13: 0 | O13: 2 | P13: 3 | Q13: 2 | R13: =IF(AND(F13="",H13=""),"",IF(SUM(F13,H13)=0,0,F13+H13)) -> 2 | S13: =IF(SUM(G13,I13)=0,"",G13+I13) -> 5 | T13: =IF(SUM(F13,H13,J13)=0,"",F13*2+H13*3+J13) -> 4 | U13: =IF(S13="","",IF(R13="",0,R13/S13)) -> 0.4 | V13: =IF(K13=0,"",J13/K13)
A14: 2 | B14: 46230 | C14: Green | E14: Ethan Hu | F14: 0 | G14: 3 | H14: 1 | I14: 6 | J14: 1 | K14: 2 | L14: 3 | M14: 3 | N14: 1 | O14: 0 | P14: 0 | Q14: 0 | R14: =IF(AND(F14="",H14=""),"",IF(SUM(F14,H14)=0,0,F14+H14)) -> 1 | S14: =IF(SUM(G14,I14)=0,"",G14+I14) -> 9 | T14: =IF(SUM(F14,H14,J14)=0,"",F14*2+H14*3+J14) -> 4 | U14: =IF(S14="","",IF(R14="",0,R14/S14)) -> 0.11111111 | V14: =IF(K14=0,"",J14/K14) -> 0.5
A15: 2 | B15: 46230 | C15: Green | E15: Kenny Liou | F15: 1 | G15: 2 | H15: 0 | I15: 0 | J15: 2 | K15: 3 | L15: 3 | M15: 5 | N15: 2 | O15: 1 | P15: 2 | Q15: 0 | R15: =IF(AND(F15="",H15=""),"",IF(SUM(F15,H15)=0,0,F15+H15)) -> 1 | S15: =IF(SUM(G15,I15)=0,"",G15+I15) -> 2 | T15: =IF(SUM(F15,H15,J15)=0,"",F15*2+H15*3+J15) -> 4 | U15: =IF(S15="","",IF(R15="",0,R15/S15)) -> 0.5 | V15: =IF(K15=0,"",J15/K15) -> 0.66666667
A16: 2 | B16: 46230 | C16: Green | E16: Markus Wong | R16: =IF(AND(F16="",H16=""),"",IF(SUM(F16,H16)=0,0,F16+H16)) | S16: =IF(SUM(G16,I16)=0,"",G16+I16) | T16: =IF(SUM(F16,H16,J16)=0,"",F16*2+H16*3+J16) | U16: =IF(S16="","",IF(R16="",0,R16/S16)) | V16: =IF(K16=0,"",J16/K16)
A17: 2 | B17: 46230 | C17: Green | E17: Thomas N | F17: 0 | G17: 2 | H17: 1 | I17: 1 | J17: 0 | K17: 0 | L17: 0 | M17: 1 | N17: 1 | O17: 0 | P17: 0 | Q17: 0 | R17: =IF(AND(F17="",H17=""),"",IF(SUM(F17,H17)=0,0,F17+H17)) -> 1 | S17: =IF(SUM(G17,I17)=0,"",G17+I17) -> 3 | T17: =IF(SUM(F17,H17,J17)=0,"",F17*2+H17*3+J17) -> 3 | U17: =IF(S17="","",IF(R17="",0,R17/S17)) -> 0.33333333 | V17: =IF(K17=0,"",J17/K17)
A18: 2 | B18: 46230 | C18: Green | E18: Arjun V | F18: 1 | G18: 9 | H18: 3 | I18: 12 | J18: 0 | K18: 0 | L18: 1 | M18: 0 | N18: 1 | O18: 4 | P18: 3 | Q18: 0 | R18: =IF(AND(F18="",H18=""),"",IF(SUM(F18,H18)=0,0,F18+H18)) -> 4 | S18: =IF(SUM(G18,I18)=0,"",G18+I18) -> 21 | T18: =IF(SUM(F18,H18,J18)=0,"",F18*2+H18*3+J18) -> 11 | U18: =IF(S18="","",IF(R18="",0,R18/S18)) -> 0.19047619 | V18: =IF(K18=0,"",J18/K18)
A19: 2 | B19: 46230 | C19: Green | E19: Will | F19: 0 | G19: 1 | H19: 0 | I19: 1 | J19: 0 | K19: 0 | L19: 2 | M19: 0 | N19: 0 | O19: 0 | P19: 0 | Q19: 0 | R19: =IF(AND(F19="",H19=""),"",IF(SUM(F19,H19)=0,0,F19+H19)) -> 0 | S19: =IF(SUM(G19,I19)=0,"",G19+I19) -> 2 | T19: =IF(SUM(F19,H19,J19)=0,"",F19*2+H19*3+J19) | U19: =IF(S19="","",IF(R19="",0,R19/S19)) -> 0 | V19: =IF(K19=0,"",J19/K19)
A20: 2 | B20: 46230 | C20: Green | E20: Steven | F20: 0 | G20: 0 | H20: 0 | I20: 1 | J20: 0 | K20: 0 | L20: 0 | M20: 0 | N20: 0 | O20: 0 | P20: 0 | Q20: 0 | R20: =IF(AND(F20="",H20=""),"",IF(SUM(F20,H20)=0,0,F20+H20)) -> 0 | S20: =IF(SUM(G20,I20)=0,"",G20+I20) -> 1 | T20: =IF(SUM(F20,H20,J20)=0,"",F20*2+H20*3+J20) | U20: =IF(S20="","",IF(R20="",0,R20/S20)) -> 0 | V20: =IF(K20=0,"",J20/K20)
A21: 3 | B21: 46237 | C21: Blue | E21: Brendan Wong | F21: 5 | G21: 11 | H21: 0 | I21: 6 | J21: 1 | K21: 5 | L21: 4 | M21: 0 | N21: 3 | O21: 3 | P21: 1 | Q21: 0 | R21: =IF(AND(F21="",H21=""),"",IF(SUM(F21,H21)=0,0,F21+H21)) -> 5 | S21: =IF(SUM(G21,I21)=0,"",G21+I21) -> 17 | T21: =IF(SUM(F21,H21,J21)=0,"",F21*2+H21*3+J21) -> 11 | U21: =IF(S21="","",IF(R21="",0,R21/S21)) -> 0.29411765 | V21: =IF(K21=0,"",J21/K21) -> 0.2
A22: 3 | B22: 46237 | C22: Blue | E22: Siddarth D | F22: 1 | G22: 3 | H22: 0 | I22: 0 | J22: 1 | K22: 2 | L22: 4 | M22: 3 | N22: 0 | O22: 6 | P22: 3 | Q22: 4 | R22: =IF(AND(F22="",H22=""),"",IF(SUM(F22,H22)=0,0,F22+H22)) -> 1 | S22: =IF(SUM(G22,I22)=0,"",G22+I22) -> 3 | T22: =IF(SUM(F22,H22,J22)=0,"",F22*2+H22*3+J22) -> 3 | U22: =IF(S22="","",IF(R22="",0,R22/S22)) -> 0.33333333 | V22: =IF(K22=0,"",J22/K22) -> 0.5
A23: 3 | B23: 46237 | C23: Blue | E23: Ethan Hu | F23: 0 | G23: 0 | H23: 0 | I23: 1 | J23: 0 | K23: 0 | L23: 3 | M23: 0 | N23: 0 | O23: 3 | P23: 0 | Q23: 0 | R23: =IF(AND(F23="",H23=""),"",IF(SUM(F23,H23)=0,0,F23+H23)) -> 0 | S23: =IF(SUM(G23,I23)=0,"",G23+I23) -> 1 | T23: =IF(SUM(F23,H23,J23)=0,"",F23*2+H23*3+J23) | U23: =IF(S23="","",IF(R23="",0,R23/S23)) -> 0 | V23: =IF(K23=0,"",J23/K23)
A24: 3 | B24: 46237 | C24: Blue | E24: Max Lee | F24: 0 | G24: 1 | H24: 0 | I24: 3 | J24: 0 | K24: 0 | L24: 3 | M24: 2 | N24: 1 | O24: 2 | P24: 1 | Q24: 0 | R24: =IF(AND(F24="",H24=""),"",IF(SUM(F24,H24)=0,0,F24+H24)) -> 0 | S24: =IF(SUM(G24,I24)=0,"",G24+I24) -> 4 | T24: =IF(SUM(F24,H24,J24)=0,"",F24*2+H24*3+J24) | U24: =IF(S24="","",IF(R24="",0,R24/S24)) -> 0 | V24: =IF(K24=0,"",J24/K24)
A25: 3 | B25: 46237 | C25: Blue | E25: Xuanyi W | F25: 0 | G25: 1 | H25: 0 | I25: 0 | J25: 0 | K25: 0 | L25: 0 | M25: 0 | N25: 0 | O25: 0 | P25: 0 | Q25: 0 | R25: =IF(AND(F25="",H25=""),"",IF(SUM(F25,H25)=0,0,F25+H25)) -> 0 | S25: =IF(SUM(G25,I25)=0,"",G25+I25) -> 1 | T25: =IF(SUM(F25,H25,J25)=0,"",F25*2+H25*3+J25) | U25: =IF(S25="","",IF(R25="",0,R25/S25)) -> 0 | V25: =IF(K25=0,"",J25/K25)
A26: 3 | B26: 46237 | C26: Blue | E26: Markus Wong | F26: 0 | G26: 0 | H26: 0 | I26: 0 | J26: 0 | K26: 0 | L26: 0 | M26: 0 | N26: 0 | O26: 1 | P26: 0 | Q26: 0 | R26: =IF(AND(F26="",H26=""),"",IF(SUM(F26,H26)=0,0,F26+H26)) -> 0 | S26: =IF(SUM(G26,I26)=0,"",G26+I26) | T26: =IF(SUM(F26,H26,J26)=0,"",F26*2+H26*3+J26) | U26: =IF(S26="","",IF(R26="",0,R26/S26)) | V26: =IF(K26=0,"",J26/K26)
A27: 3 | B27: 46237 | C27: Blue | E27: Thomas N | F27: 0 | G27: 2 | H27: 0 | I27: 2 | J27: 0 | K27: 0 | L27: 0 | M27: 1 | N27: 0 | O27: 0 | P27: 0 | Q27: 0 | R27: =IF(AND(F27="",H27=""),"",IF(SUM(F27,H27)=0,0,F27+H27)) -> 0 | S27: =IF(SUM(G27,I27)=0,"",G27+I27) -> 4 | T27: =IF(SUM(F27,H27,J27)=0,"",F27*2+H27*3+J27) | U27: =IF(S27="","",IF(R27="",0,R27/S27)) -> 0 | V27: =IF(K27=0,"",J27/K27)
A28: 3 | B28: 46237 | C28: Blue | E28: Arjun V | F28: 2 | G28: 6 | H28: 4 | I28: 6 | J28: 2 | K28: 2 | L28: 4 | M28: 1 | N28: 1 | O28: 3 | P28: 0 | Q28: 1 | R28: =IF(AND(F28="",H28=""),"",IF(SUM(F28,H28)=0,0,F28+H28)) -> 6 | S28: =IF(SUM(G28,I28)=0,"",G28+I28) -> 12 | T28: =IF(SUM(F28,H28,J28)=0,"",F28*2+H28*3+J28) -> 18 | U28: =IF(S28="","",IF(R28="",0,R28/S28)) -> 0.5 | V28: =IF(K28=0,"",J28/K28) -> 1
... A32: 3 | B32: 46237 | C32: Blue | E32: Vee | F32: 1 | G32: 4 | H32: 0 | I32: 1 | J32: 1 | K32: 3 | L32: 9 | M32: 3 | N32: 1 | O32: 1 | P32: 0 | Q32: 0 | R32: =IF(AND(F32="",H32=""),"",IF(SUM(F32,H32)=0,0,F32+H32)) -> 1 | S32: =IF(SUM(G32,I32)=0,"",G32+I32) -> 5 | T32: =IF(SUM(F32,H32,J32)=0,"",F32*2+H32*3+J32) -> 3 | U32: =IF(S32="","",IF(R32="",0,R32/S32)) -> 0.2 | V32: =IF(K32=0,"",J32/K32) -> 0.33333333
R33: =IF(AND(F33="",H33=""),"",IF(SUM(F33,H33)=0,0,F33+H33)) | S33: =IF(SUM(G33,I33)=0,"",G33+I33) | T33: =IF(SUM(F33,H33,J33)=0,"",F33*2+H33*3+J33) | U33: =IF(S33="","",IF(R33="",0,R33/S33)) | V33: =IF(K33=0,"",J33/K33)
R34: =IF(AND(F34="",H34=""),"",IF(SUM(F34,H34)=0,0,F34+H34)) | S34: =IF(SUM(G34,I34)=0,"",G34+I34) | T34: =IF(SUM(F34,H34,J34)=0,"",F34*2+H34*3+J34) | U34: =IF(S34="","",IF(R34="",0,R34/S34)) | V34: =IF(K34=0,"",J34/K34)
R35: =IF(AND(F35="",H35=""),"",IF(SUM(F35,H35)=0,0,F35+H35)) | S35: =IF(SUM(G35,I35)=0,"",G35+I35) | T35: =IF(SUM(F35,H35,J35)=0,"",F35*2+H35*3+J35) | U35: =IF(S35="","",IF(R35="",0,R35/S35)) | V35: =IF(K35=0,"",J35/K35)
R36: =IF(AND(F36="",H36=""),"",IF(SUM(F36,H36)=0,0,F36+H36)) | S36: =IF(SUM(G36,I36)=0,"",G36+I36) | T36: =IF(SUM(F36,H36,J36)=0,"",F36*2+H36*3+J36) | U36: =IF(S36="","",IF(R36="",0,R36/S36)) | V36: =IF(K36=0,"",J36/K36)
R37: =IF(AND(F37="",H37=""),"",IF(SUM(F37,H37)=0,0,F37+H37)) | S37: =IF(SUM(G37,I37)=0,"",G37+I37) | T37: =IF(SUM(F37,H37,J37)=0,"",F37*2+H37*3+J37) | U37: =IF(S37="","",IF(R37="",0,R37/S37)) | V37: =IF(K37=0,"",J37/K37)
R38: =IF(AND(F38="",H38=""),"",IF(SUM(F38,H38)=0,0,F38+H38)) | S38: =IF(SUM(G38,I38)=0,"",G38+I38) | T38: =IF(SUM(F38,H38,J38)=0,"",F38*2+H38*3+J38) | U38: =IF(S38="","",IF(R38="",0,R38/S38)) | V38: =IF(K38=0,"",J38/K38)
R39: =IF(AND(F39="",H39=""),"",IF(SUM(F39,H39)=0,0,F39+H39)) | S39: =IF(SUM(G39,I39)=0,"",G39+I39) | T39: =IF(SUM(F39,H39,J39)=0,"",F39*2+H39*3+J39) | U39: =IF(S39="","",IF(R39="",0,R39/S39)) | V39: =IF(K39=0,"",J39/K39)
R40: =IF(AND(F40="",H40=""),"",IF(SUM(F40,H40)=0,0,F40+H40)) | S40: =IF(SUM(G40,I40)=0,"",G40+I40) | T40: =IF(SUM(F40,H40,J40)=0,"",F40*2+H40*3+J40) | U40: =IF(S40="","",IF(R40="",0,R40/S40)) | V40: =IF(K40=0,"",J40/K40)
R41: =IF(AND(F41="",H41=""),"",IF(SUM(F41,H41)=0,0,F41+H41)) | S41: =IF(SUM(G41,I41)=0,"",G41+I41) | T41: =IF(SUM(F41,H41,J41)=0,"",F41*2+H41*3+J41) | U41: =IF(S41="","",IF(R41="",0,R41/S41)) | V41: =IF(K41=0,"",J41/K41)
R42: =IF(AND(F42="",H42=""),"",IF(SUM(F42,H42)=0,0,F42+H42)) | S42: =IF(SUM(G42,I42)=0,"",G42+I42) | T42: =IF(SUM(F42,H42,J42)=0,"",F42*2+H42*3+J42) | U42: =IF(S42="","",IF(R42="",0,R42/S42)) | V42: =IF(K42=0,"",J42/K42)
R43: =IF(AND(F43="",H43=""),"",IF(SUM(F43,H43)=0,0,F43+H43)) | S43: =IF(SUM(G43,I43)=0,"",G43+I43) | T43: =IF(SUM(F43,H43,J43)=0,"",F43*2+H43*3+J43) | U43: =IF(S43="","",IF(R43="",0,R43/S43)) | V43: =IF(K43=0,"",J43/K43)
R44: =IF(AND(F44="",H44=""),"",IF(SUM(F44,H44)=0,0,F44+H44)) | S44: =IF(SUM(G44,I44)=0,"",G44+I44) | T44: =IF(SUM(F44,H44,J44)=0,"",F44*2+H44*3+J44) | U44: =IF(S44="","",IF(R44="",0,R44/S44)) | V44: =IF(K44=0,"",J44/K44)
...

Sheet Team Game Log
A1: Team Game Log | B1: Team Game Log | C1: Team Game Log | D1: Team Game Log | E1: Team Game Log | F1: Team Game Log | G1: Team Game Log | H1: Team Game Log | I1: Team Game Log | J1: Team Game Log | K1: Team Game Log | L1: Team Game Log | M1: Team Game Log | N1: Team Game Log | O1: Team Game Log | P1: Team Game Log | Q1: Team Game Log | R1: Team Game Log | S1: Team Game Log | T1: Team Game Log | U1: Team Game Log | V1: Team Game Log
A3: Game ID | B3: Date | C3: Opponent | D3: Our Q1 End Total | E3: Our Final Total | F3: Opp Q1 End Total | G3: Opp Final Total | H3: Our Q1 Points | I3: Our Q2 Points | J3: Opp Q1 Points | K3: Opp Q2 Points | L3: Result | M3: Margin | N3: 2PM | O3: 2PA | P3: 3PM | Q3: 3PA | R3: FGM | S3: FGA | T3: FTM | U3: FTA | V3: DREB | W3: OREB | X3: AST | Y3: TO | Z3: STL | AA3: BLK | AB3: Turnout | AC3: Player Rows Linked?
A4: 1 | B4: 46223 | C4: White | D4: 17 | E4: 31 | F4: 31 | G4: 67 | H4: =IF($A4="","",IF(D4="","",D4)) -> 17 | I4: =IF($A4="","",IF(OR(D4="",E4=""),"",E4-D4)) -> 14 | J4: =IF($A4="","",IF(F4="","",F4)) -> 31 | K4: =IF($A4="","",IF(OR(F4="",G4=""),"",G4-F4)) -> 36 | L4: =IF($A4="","",IF(OR(E4="",G4=""),"",IF(E4>G4,"W",IF(E4<G4,"L","T")))) -> L | M4: =IF($A4="","",IF(OR(E4="",G4=""),"",E4-G4)) -> -36 | N4: =IF($A4="","",SUMIFS('Player Game Log'!$F$4:$F$603,'Player Game Log'!$A$4:$A$603,A4)) -> 10 | O4: =IF($A4="","",SUMIFS('Player Game Log'!$G$4:$G$603,'Player Game Log'!$A$4:$A$603,A4)) -> 30 | P4: =IF($A4="","",SUMIFS('Player Game Log'!$H$4:$H$603,'Player Game Log'!$A$4:$A$603,A4)) -> 2 | Q4: =IF($A4="","",SUMIFS('Player Game Log'!$I$4:$I$603,'Player Game Log'!$A$4:$A$603,A4)) -> 30 | R4: =IF($A4="","",SUMIFS('Player Game Log'!$R$4:$R$603,'Player Game Log'!$A$4:$A$603,A4)) -> 12 | S4: =IF($A4="","",SUMIFS('Player Game Log'!$S$4:$S$603,'Player Game Log'!$A$4:$A$603,A4)) -> 60 | T4: =IF($A4="","",SUMIFS('Player Game Log'!$J$4:$J$603,'Player Game Log'!$A$4:$A$603,A4)) -> 5 | U4: =IF($A4="","",SUMIFS('Player Game Log'!$K$4:$K$603,'Player Game Log'!$A$4:$A$603,A4)) -> 11 | V4: =IF($A4="","",SUMIFS('Player Game Log'!$L$4:$L$603,'Player Game Log'!$A$4:$A$603,A4)) -> 24 | W4: =IF($A4="","",SUMIFS('Player Game Log'!$M$4:$M$603,'Player Game Log'!$A$4:$A$603,A4)) -> 3 | X4: =IF($A4="","",SUMIFS('Player Game Log'!$N$4:$N$603,'Player Game Log'!$A$4:$A$603,A4)) -> 2 | Y4: =IF($A4="","",SUMIFS('Player Game Log'!$O$4:$O$603,'Player Game Log'!$A$4:$A$603,A4)) -> 4 | Z4: =IF($A4="","",SUMIFS('Player Game Log'!$P$4:$P$603,'Player Game Log'!$A$4:$A$603,A4)) -> 4 | AA4: =IF($A4="","",SUMIFS('Player Game Log'!$Q$4:$Q$603,'Player Game Log'!$A$4:$A$603,A4)) -> 0 | AB4: =IF($A4="","",COUNTIFS('Player Game Log'!$A$4:$A$603,A4)) -> 8 | AC4: =IF($A4="","",IF(COUNTIFS('Player Game Log'!$A$4:$A$603,A4)>0,"Yes","No")) -> Yes
A5: 2 | B5: 46230 | C5: Green | D5: 12 | E5: 33 | F5: 17 | G5: 38 | H5: =IF($A5="","",IF(D5="","",D5)) -> 12 | I5: =IF($A5="","",IF(OR(D5="",E5=""),"",E5-D5)) -> 21 | J5: =IF($A5="","",IF(F5="","",F5)) -> 17 | K5: =IF($A5="","",IF(OR(F5="",G5=""),"",G5-F5)) -> 21 | L5: =IF($A5="","",IF(OR(E5="",G5=""),"",IF(E5>G5,"W",IF(E5<G5,"L","T")))) -> L | M5: =IF($A5="","",IF(OR(E5="",G5=""),"",E5-G5)) -> -5 | N5: =IF($A5="","",SUMIFS('Player Game Log'!$F$4:$F$603,'Player Game Log'!$A$4:$A$603,A5)) -> 6 | O5: =IF($A5="","",SUMIFS('Player Game Log'!$G$4:$G$603,'Player Game Log'!$A$4:$A$603,A5)) -> 30 | P5: =IF($A5="","",SUMIFS('Player Game Log'!$H$4:$H$603,'Player Game Log'!$A$4:$A$603,A5)) -> 5 | Q5: =IF($A5="","",SUMIFS('Player Game Log'!$I$4:$I$603,'Player Game Log'!$A$4:$A$603,A5)) -> 25 | R5: =IF($A5="","",SUMIFS('Player Game Log'!$R$4:$R$603,'Player Game Log'!$A$4:$A$603,A5)) -> 11 | S5: =IF($A5="","",SUMIFS('Player Game Log'!$S$4:$S$603,'Player Game Log'!$A$4:$A$603,A5)) -> 55 | T5: =IF($A5="","",SUMIFS('Player Game Log'!$J$4:$J$603,'Player Game Log'!$A$4:$A$603,A5)) -> 6 | U5: =IF($A5="","",SUMIFS('Player Game Log'!$K$4:$K$603,'Player Game Log'!$A$4:$A$603,A5)) -> 18 | V5: =IF($A5="","",SUMIFS('Player Game Log'!$L$4:$L$603,'Player Game Log'!$A$4:$A$603,A5)) -> 19 | W5: =IF($A5="","",SUMIFS('Player Game Log'!$M$4:$M$603,'Player Game Log'!$A$4:$A$603,A5)) -> 13 | X5: =IF($A5="","",SUMIFS('Player Game Log'!$N$4:$N$603,'Player Game Log'!$A$4:$A$603,A5)) -> 7 | Y5: =IF($A5="","",SUMIFS('Player Game Log'!$O$4:$O$603,'Player Game Log'!$A$4:$A$603,A5)) -> 10 | Z5: =IF($A5="","",SUMIFS('Player Game Log'!$P$4:$P$603,'Player Game Log'!$A$4:$A$603,A5)) -> 10 | AA5: =IF($A5="","",SUMIFS('Player Game Log'!$Q$4:$Q$603,'Player Game Log'!$A$4:$A$603,A5)) -> 2 | AB5: =IF($A5="","",COUNTIFS('Player Game Log'!$A$4:$A$603,A5)) -> 9 | AC5: =IF($A5="","",IF(COUNTIFS('Player Game Log'!$A$4:$A$603,A5)>0,"Yes","No")) -> Yes
A6: 3 | B6: 46237 | C6: Blue | D6: 20 | E6: 41 | F6: 21 | G6: 38 | H6: =IF($A6="","",IF(D6="","",D6)) -> 20 | I6: =IF($A6="","",IF(OR(D6="",E6=""),"",E6-D6)) -> 21 | J6: =IF($A6="","",IF(F6="","",F6)) -> 21 | K6: =IF($A6="","",IF(OR(F6="",G6=""),"",G6-F6)) -> 17 | L6: =IF($A6="","",IF(OR(E6="",G6=""),"",IF(E6>G6,"W",IF(E6<G6,"L","T")))) -> W | M6: =IF($A6="","",IF(OR(E6="",G6=""),"",E6-G6)) -> 3 | N6: =IF($A6="","",SUMIFS('Player Game Log'!$F$4:$F$603,'Player Game Log'!$A$4:$A$603,A6)) -> 12 | O6: =IF($A6="","",SUMIFS('Player Game Log'!$G$4:$G$603,'Player Game Log'!$A$4:$A$603,A6)) -> 34 | P6: =IF($A6="","",SUMIFS('Player Game Log'!$H$4:$H$603,'Player Game Log'!$A$4:$A$603,A6)) -> 4 | Q6: =IF($A6="","",SUMIFS('Player Game Log'!$I$4:$I$603,'Player Game Log'!$A$4:$A$603,A6)) -> 21 | R6: =IF($A6="","",SUMIFS('Player Game Log'!$R$4:$R$603,'Player Game Log'!$A$4:$A$603,A6)) -> 16 | S6: =IF($A6="","",SUMIFS('Player Game Log'!$S$4:$S$603,'Player Game Log'!$A$4:$A$603,A6)) -> 55 | T6: =IF($A6="","",SUMIFS('Player Game Log'!$J$4:$J$603,'Player Game Log'!$A$4:$A$603,A6)) -> 5 | U6: =IF($A6="","",SUMIFS('Player Game Log'!$K$4:$K$603,'Player Game Log'!$A$4:$A$603,A6)) -> 12 | V6: =IF($A6="","",SUMIFS('Player Game Log'!$L$4:$L$603,'Player Game Log'!$A$4:$A$603,A6)) -> 33 | W6: =IF($A6="","",SUMIFS('Player Game Log'!$M$4:$M$603,'Player Game Log'!$A$4:$A$603,A6)) -> 11 | X6: =IF($A6="","",SUMIFS('Player Game Log'!$N$4:$N$603,'Player Game Log'!$A$4:$A$603,A6)) -> 6 | Y6: =IF($A6="","",SUMIFS('Player Game Log'!$O$4:$O$603,'Player Game Log'!$A$4:$A$603,A6)) -> 20 | Z6: =IF($A6="","",SUMIFS('Player Game Log'!$P$4:$P$603,'Player Game Log'!$A$4:$A$603,A6)) -> 6 | AA6: =IF($A6="","",SUMIFS('Player Game Log'!$Q$4:$Q$603,'Player Game Log'!$A$4:$A$603,A6)) -> 6 | AB6: =IF($A6="","",COUNTIFS('Player Game Log'!$A$4:$A$603,A6)) -> 12 | AC6: =IF($A6="","",IF(COUNTIFS('Player Game Log'!$A$4:$A$603,A6)>0,"Yes","No")) -> Yes
H7: =IF($A7="","",IF(D7="","",D7)) | I7: =IF($A7="","",IF(OR(D7="",E7=""),"",E7-D7)) | J7: =IF($A7="","",IF(F7="","",F7)) | K7: =IF($A7="","",IF(OR(F7="",G7=""),"",G7-F7)) | L7: =IF($A7="","",IF(OR(E7="",G7=""),"",IF(E7>G7,"W",IF(E7<G7,"L","T")))) | M7: =IF($A7="","",IF(OR(E7="",G7=""),"",E7-G7)) | N7: =IF($A7="","",SUMIFS('Player Game Log'!$F$4:$F$603,'Player Game Log'!$A$4:$A$603,A7)) | O7: =IF($A7="","",SUMIFS('Player Game Log'!$G$4:$G$603,'Player Game Log'!$A$4:$A$603,A7)) | P7: =IF($A7="","",SUMIFS('Player Game Log'!$H$4:$H$603,'Player Game Log'!$A$4:$A$603,A7)) | Q7: =IF($A7="","",SUMIFS('Player Game Log'!$I$4:$I$603,'Player Game Log'!$A$4:$A$603,A7)) | R7: =IF($A7="","",SUMIFS('Player Game Log'!$R$4:$R$603,'Player Game Log'!$A$4:$A$603,A7)) | S7: =IF($A7="","",SUMIFS('Player Game Log'!$S$4:$S$603,'Player Game Log'!$A$4:$A$603,A7)) | T7: =IF($A7="","",SUMIFS('Player Game Log'!$J$4:$J$603,'Player Game Log'!$A$4:$A$603,A7)) | U7: =IF($A7="","",SUMIFS('Player Game Log'!$K$4:$K$603,'Player Game Log'!$A$4:$A$603,A7)) | V7: =IF($A7="","",SUMIFS('Player Game Log'!$L$4:$L$603,'Player Game Log'!$A$4:$A$603,A7)) | W7: =IF($A7="","",SUMIFS('Player Game Log'!$M$4:$M$603,'Player Game Log'!$A$4:$A$603,A7)) | X7: =IF($A7="","",SUMIFS('Player Game Log'!$N$4:$N$603,'Player Game Log'!$A$4:$A$603,A7)) | Y7: =IF($A7="","",SUMIFS('Player Game Log'!$O$4:$O$603,'Player Game Log'!$A$4:$A$603,A7)) | Z7: =IF($A7="","",SUMIFS('Player Game Log'!$P$4:$P$603,'Player Game Log'!$A$4:$A$603,A7)) | AA7: =IF($A7="","",SUMIFS('Player Game Log'!$Q$4:$Q$603,'Player Game Log'!$A$4:$A$603,A7)) | AB7: =IF($A7="","",COUNTIFS('Player Game Log'!$A$4:$A$603,A7)) | AC7: =IF($A7="","",IF(COUNTIFS('Player Game Log'!$A$4:$A$603,A7)>0,"Yes","No"))
H8: =IF($A8="","",IF(D8="","",D8)) | I8: =IF($A8="","",IF(OR(D8="",E8=""),"",E8-D8)) | J8: =IF($A8="","",IF(F8="","",F8)) | K8: =IF($A8="","",IF(OR(F8="",G8=""),"",G8-F8)) | L8: =IF($A8="","",IF(OR(E8="",G8=""),"",IF(E8>G8,"W",IF(E8<G8,"L","T")))) | M8: =IF($A8="","",IF(OR(E8="",G8=""),"",E8-G8)) | N8: =IF($A8="","",SUMIFS('Player Game Log'!$F$4:$F$603,'Player Game Log'!$A$4:$A$603,A8)) | O8: =IF($A8="","",SUMIFS('Player Game Log'!$G$4:$G$603,'Player Game Log'!$A$4:$A$603,A8)) | P8: =IF($A8="","",SUMIFS('Player Game Log'!$H$4:$H$603,'Player Game Log'!$A$4:$A$603,A8)) | Q8: =IF($A8="","",SUMIFS('Player Game Log'!$I$4:$I$603,'Player Game Log'!$A$4:$A$603,A8)) | R8: =IF($A8="","",SUMIFS('Player Game Log'!$R$4:$R$603,'Player Game Log'!$A$4:$A$603,A8)) | S8: =IF($A8="","",SUMIFS('Player Game Log'!$S$4:$S$603,'Player Game Log'!$A$4:$A$603,A8)) | T8: =IF($A8="","",SUMIFS('Player Game Log'!$J$4:$J$603,'Player Game Log'!$A$4:$A$603,A8)) | U8: =IF($A8="","",SUMIFS('Player Game Log'!$K$4:$K$603,'Player Game Log'!$A$4:$A$603,A8)) | V8: =IF($A8="","",SUMIFS('Player Game Log'!$L$4:$L$603,'Player Game Log'!$A$4:$A$603,A8)) | W8: =IF($A8="","",SUMIFS('Player Game Log'!$M$4:$M$603,'Player Game Log'!$A$4:$A$603,A8)) | X8: =IF($A8="","",SUMIFS('Player Game Log'!$N$4:$N$603,'Player Game Log'!$A$4:$A$603,A8)) | Y8: =IF($A8="","",SUMIFS('Player Game Log'!$O$4:$O$603,'Player Game Log'!$A$4:$A$603,A8)) | Z8: =IF($A8="","",SUMIFS('Player Game Log'!$P$4:$P$603,'Player Game Log'!$A$4:$A$603,A8)) | AA8: =IF($A8="","",SUMIFS('Player Game Log'!$Q$4:$Q$603,'Player Game Log'!$A$4:$A$603,A8)) | AB8: =IF($A8="","",COUNTIFS('Player Game Log'!$A$4:$A$603,A8)) | AC8: =IF($A8="","",IF(COUNTIFS('Player Game Log'!$A$4:$A$603,A8)>0,"Yes","No"))
H9: =IF($A9="","",IF(D9="","",D9)) | I9: =IF($A9="","",IF(OR(D9="",E9=""),"",E9-D9)) | J9: =IF($A9="","",IF(F9="","",F9)) | K9: =IF($A9="","",IF(OR(F9="",G9=""),"",G9-F9)) | L9: =IF($A9="","",IF(OR(E9="",G9=""),"",IF(E9>G9,"W",IF(E9<G9,"L","T")))) | M9: =IF($A9="","",IF(OR(E9="",G9=""),"",E9-G9)) | N9: =IF($A9="","",SUMIFS('Player Game Log'!$F$4:$F$603,'Player Game Log'!$A$4:$A$603,A9)) | O9: =IF($A9="","",SUMIFS('Player Game Log'!$G$4:$G$603,'Player Game Log'!$A$4:$A$603,A9)) | P9: =IF($A9="","",SUMIFS('Player Game Log'!$H$4:$H$603,'Player Game Log'!$A$4:$A$603,A9)) | Q9: =IF($A9="","",SUMIFS('Player Game Log'!$I$4:$I$603,'Player Game Log'!$A$4:$A$603,A9)) | R9: =IF($A9="","",SUMIFS('Player Game Log'!$R$4:$R$603,'Player Game Log'!$A$4:$A$603,A9)) | S9: =IF($A9="","",SUMIFS('Player Game Log'!$S$4:$S$603,'Player Game Log'!$A$4:$A$603,A9)) | T9: =IF($A9="","",SUMIFS('Player Game Log'!$J$4:$J$603,'Player Game Log'!$A$4:$A$603,A9)) | U9: =IF($A9="","",SUMIFS('Player Game Log'!$K$4:$K$603,'Player Game Log'!$A$4:$A$603,A9)) | V9: =IF($A9="","",SUMIFS('Player Game Log'!$L$4:$L$603,'Player Game Log'!$A$4:$A$603,A9)) | W9: =IF($A9="","",SUMIFS('Player Game Log'!$M$4:$M$603,'Player Game Log'!$A$4:$A$603,A9)) | X9: =IF($A9="","",SUMIFS('Player Game Log'!$N$4:$N$603,'Player Game Log'!$A$4:$A$603,A9)) | Y9: =IF($A9="","",SUMIFS('Player Game Log'!$O$4:$O$603,'Player Game Log'!$A$4:$A$603,A9)) | Z9: =IF($A9="","",SUMIFS('Player Game Log'!$P$4:$P$603,'Player Game Log'!$A$4:$A$603,A9)) | AA9: =IF($A9="","",SUMIFS('Player Game Log'!$Q$4:$Q$603,'Player Game Log'!$A$4:$A$603,A9)) | AB9: =IF($A9="","",COUNTIFS('Player Game Log'!$A$4:$A$603,A9)) | AC9: =IF($A9="","",IF(COUNTIFS('Player Game Log'!$A$4:$A$603,A9)>0,"Yes","No"))
H10: =IF($A10="","",IF(D10="","",D10)) | I10: =IF($A10="","",IF(OR(D10="",E10=""),"",E10-D10)) | J10: =IF($A10="","",IF(F10="","",F10)) | K10: =IF($A10="","",IF(OR(F10="",G10=""),"",G10-F10)) | L10: =IF($A10="","",IF(OR(E10="",G10=""),"",IF(E10>G10,"W",IF(E10<G10,"L","T")))) | M10: =IF($A10="","",IF(OR(E10="",G10=""),"",E10-G10)) | N10: =IF($A10="","",SUMIFS('Player Game Log'!$F$4:$F$603,'Player Game Log'!$A$4:$A$603,A10)) | O10: =IF($A10="","",SUMIFS('Player Game Log'!$G$4:$G$603,'Player Game Log'!$A$4:$A$603,A10)) | P10: =IF($A10="","",SUMIFS('Player Game Log'!$H$4:$H$603,'Player Game Log'!$A$4:$A$603,A10)) | Q10: =IF($A10="","",SUMIFS('Player Game Log'!$I$4:$I$603,'Player Game Log'!$A$4:$A$603,A10)) | R10: =IF($A10="","",SUMIFS('Player Game Log'!$R$4:$R$603,'Player Game Log'!$A$4:$A$603,A10)) | S10: =IF($A10="","",SUMIFS('Player Game Log'!$S$4:$S$603,'Player Game Log'!$A$4:$A$603,A10)) | T10: =IF($A10="","",SUMIFS('Player Game Log'!$J$4:$J$603,'Player Game Log'!$A$4:$A$603,A10)) | U10: =IF($A10="","",SUMIFS('Player Game Log'!$K$4:$K$603,'Player Game Log'!$A$4:$A$603,A10)) | V10: =IF($A10="","",SUMIFS('Player Game Log'!$L$4:$L$603,'Player Game Log'!$A$4:$A$603,A10)) | W10: =IF($A10="","",SUMIFS('Player Game Log'!$M$4:$M$603,'Player Game Log'!$A$4:$A$603,A10)) | X10: =IF($A10="","",SUMIFS('Player Game Log'!$N$4:$N$603,'Player Game Log'!$A$4:$A$603,A10)) | Y10: =IF($A10="","",SUMIFS('Player Game Log'!$O$4:$O$603,'Player Game Log'!$A$4:$A$603,A10)) | Z10: =IF($A10="","",SUMIFS('Player Game Log'!$P$4:$P$603,'Player Game Log'!$A$4:$A$603,A10)) | AA10: =IF($A10="","",SUMIFS('Player Game Log'!$Q$4:$Q$603,'Player Game Log'!$A$4:$A$603,A10)) | AB10: =IF($A10="","",COUNTIFS('Player Game Log'!$A$4:$A$603,A10)) | AC10: =IF($A10="","",IF(COUNTIFS('Player Game Log'!$A$4:$A$603,A10)>0,"Yes","No"))
H11: =IF($A11="","",IF(D11="","",D11)) | I11: =IF($A11="","",IF(OR(D11="",E11=""),"",E11-D11)) | J11: =IF($A11="","",IF(F11="","",F11)) | K11: =IF($A11="","",IF(OR(F11="",G11=""),"",G11-F11)) | L11: =IF($A11="","",IF(OR(E11="",G11=""),"",IF(E11>G11,"W",IF(E11<G11,"L","T")))) | M11: =IF($A11="","",IF(OR(E11="",G11=""),"",E11-G11)) | N11: =IF($A11="","",SUMIFS('Player Game Log'!$F$4:$F$603,'Player Game Log'!$A$4:$A$603,A11)) | O11: =IF($A11="","",SUMIFS('Player Game Log'!$G$4:$G$603,'Player Game Log'!$A$4:$A$603,A11)) | P11: =IF($A11="","",SUMIFS('Player Game Log'!$H$4:$H$603,'Player Game Log'!$A$4:$A$603,A11)) | Q11: =IF($A11="","",SUMIFS('Player Game Log'!$I$4:$I$603,'Player Game Log'!$A$4:$A$603,A11)) | R11: =IF($A11="","",SUMIFS('Player Game Log'!$R$4:$R$603,'Player Game Log'!$A$4:$A$603,A11)) | S11: =IF($A11="","",SUMIFS('Player Game Log'!$S$4:$S$603,'Player Game Log'!$A$4:$A$603,A11)) | T11: =IF($A11="","",SUMIFS('Player Game Log'!$J$4:$J$603,'Player Game Log'!$A$4:$A$603,A11)) | U11: =IF($A11="","",SUMIFS('Player Game Log'!$K$4:$K$603,'Player Game Log'!$A$4:$A$603,A11)) | V11: =IF($A11="","",SUMIFS('Player Game Log'!$L$4:$L$603,'Player Game Log'!$A$4:$A$603,A11)) | W11: =IF($A11="","",SUMIFS('Player Game Log'!$M$4:$M$603,'Player Game Log'!$A$4:$A$603,A11)) | X11: =IF($A11="","",SUMIFS('Player Game Log'!$N$4:$N$603,'Player Game Log'!$A$4:$A$603,A11)) | Y11: =IF($A11="","",SUMIFS('Player Game Log'!$O$4:$O$603,'Player Game Log'!$A$4:$A$603,A11)) | Z11: =IF($A11="","",SUMIFS('Player Game Log'!$P$4:$P$603,'Player Game Log'!$A$4:$A$603,A11)) | AA11: =IF($A11="","",SUMIFS('Player Game Log'!$Q$4:$Q$603,'Player Game Log'!$A$4:$A$603,A11)) | AB11: =IF($A11="","",COUNTIFS('Player Game Log'!$A$4:$A$603,A11)) | AC11: =IF($A11="","",IF(COUNTIFS('Player Game Log'!$A$4:$A$603,A11)>0,"Yes","No"))
